[2023-11-07T01:28:38.584+0000] {logging_mixin.py:151} INFO - Changing /opt/***/logs/dag_id=export_google_data_v02/run_id=scheduled__2023-11-05T00:00:00+00:00/task_id=3rd_task permission to 509
[2023-11-07T01:28:38.825+0000] {logging_mixin.py:151} INFO - Changing /opt/***/logs/dag_id=export_google_data_v02/run_id=scheduled__2023-11-05T00:00:00+00:00/task_id=3rd_task permission to 509
[2023-11-07T01:28:39.646+0000] {taskinstance.py:1159} INFO - Dependencies all met for dep_context=non-requeueable deps ti=<TaskInstance: export_google_data_v02.3rd_task scheduled__2023-11-05T00:00:00+00:00 [queued]>
[2023-11-07T01:28:39.706+0000] {taskinstance.py:1159} INFO - Dependencies all met for dep_context=requeueable deps ti=<TaskInstance: export_google_data_v02.3rd_task scheduled__2023-11-05T00:00:00+00:00 [queued]>
[2023-11-07T01:28:39.708+0000] {taskinstance.py:1361} INFO - Starting attempt 2 of 6
[2023-11-07T01:28:39.793+0000] {taskinstance.py:1382} INFO - Executing <Task(BashOperator): 3rd_task> on 2023-11-05 00:00:00+00:00
[2023-11-07T01:28:39.827+0000] {standard_task_runner.py:57} INFO - Started process 10091 to run task
[2023-11-07T01:28:39.841+0000] {standard_task_runner.py:84} INFO - Running: ['***', 'tasks', 'run', 'export_google_data_v02', '3rd_task', 'scheduled__2023-11-05T00:00:00+00:00', '--job-id', '278', '--raw', '--subdir', 'DAGS_FOLDER/export_data.py', '--cfg-path', '/tmp/tmpibt8puxp']
[2023-11-07T01:28:39.872+0000] {standard_task_runner.py:85} INFO - Job 278: Subtask 3rd_task
[2023-11-07T01:28:40.318+0000] {logging_mixin.py:151} INFO - Changing /opt/***/logs/dag_id=export_google_data_v02/run_id=scheduled__2023-11-05T00:00:00+00:00/task_id=3rd_task permission to 509
[2023-11-07T01:28:40.335+0000] {task_command.py:416} INFO - Running <TaskInstance: export_google_data_v02.3rd_task scheduled__2023-11-05T00:00:00+00:00 [running]> on host c4630ce72677
[2023-11-07T01:28:40.678+0000] {taskinstance.py:1662} INFO - Exporting env vars: AIRFLOW_CTX_DAG_OWNER='Toema' AIRFLOW_CTX_DAG_ID='export_google_data_v02' AIRFLOW_CTX_TASK_ID='3rd_task' AIRFLOW_CTX_EXECUTION_DATE='2023-11-05T00:00:00+00:00' AIRFLOW_CTX_TRY_NUMBER='2' AIRFLOW_CTX_DAG_RUN_ID='scheduled__2023-11-05T00:00:00+00:00'
[2023-11-07T01:28:40.685+0000] {subprocess.py:63} INFO - Tmp dir root location: /tmp
[2023-11-07T01:28:40.739+0000] {subprocess.py:75} INFO - Running command: ['/bin/bash', '-c', 'python /opt/***/dags/src/scripts/export_data.py']
[2023-11-07T01:28:40.776+0000] {subprocess.py:86} INFO - Output:
[2023-11-07T01:29:39.073+0000] {subprocess.py:93} INFO - Traceback (most recent call last):
[2023-11-07T01:29:39.428+0000] {subprocess.py:93} INFO -   File "/opt/***/dags/src/scripts/export_data.py", line 96, in <module>
[2023-11-07T01:29:39.467+0000] {subprocess.py:93} INFO -     license_utils.export_aggregated_license(path_utils.path_to('export_cc_by_license'),
[2023-11-07T01:29:39.477+0000] {subprocess.py:93} INFO -   File "/opt/***/dags/src/scripts/../../src/pipeline/license_utils.py", line 60, in export_aggregated_license
[2023-11-07T01:29:39.492+0000] {subprocess.py:93} INFO -     with open(export_path, 'w',encoding="UTF-8", errors="ignore") as outfile:
[2023-11-07T01:29:39.505+0000] {subprocess.py:93} INFO - FileNotFoundError: [Errno 2] No such file or directory: '/opt/***/dags/data/exports/cc_by/LICENSE'
[2023-11-07T01:29:39.879+0000] {subprocess.py:97} INFO - Command exited with return code 1
[2023-11-07T01:29:40.553+0000] {taskinstance.py:1937} ERROR - Task failed with exception
Traceback (most recent call last):
  File "/home/airflow/.local/lib/python3.8/site-packages/airflow/operators/bash.py", line 210, in execute
    raise AirflowException(
airflow.exceptions.AirflowException: Bash command failed. The command returned a non-zero exit code 1.
[2023-11-07T01:29:40.869+0000] {taskinstance.py:1400} INFO - Marking task as UP_FOR_RETRY. dag_id=export_google_data_v02, task_id=3rd_task, execution_date=20231105T000000, start_date=20231107T012839, end_date=20231107T012940
[2023-11-07T01:29:41.241+0000] {standard_task_runner.py:104} ERROR - Failed to execute job 278 for task 3rd_task (Bash command failed. The command returned a non-zero exit code 1.; 10091)
[2023-11-07T01:29:41.550+0000] {local_task_job_runner.py:228} INFO - Task exited with return code 1
[2023-11-07T01:29:42.103+0000] {taskinstance.py:2778} INFO - 0 downstream tasks scheduled from follow-on schedule check
