[2023-11-05T21:55:51.459+0000] {logging_mixin.py:151} INFO - Changing /opt/***/logs/dag_id=fetch_google_data_v03/run_id=scheduled__2023-11-04T00:00:00+00:00/task_id=3rd_task permission to 509
[2023-11-05T21:55:51.509+0000] {logging_mixin.py:151} INFO - Changing /opt/***/logs/dag_id=fetch_google_data_v03/run_id=scheduled__2023-11-04T00:00:00+00:00/task_id=3rd_task permission to 509
[2023-11-05T21:55:51.577+0000] {taskinstance.py:1159} INFO - Dependencies all met for dep_context=non-requeueable deps ti=<TaskInstance: fetch_google_data_v03.3rd_task scheduled__2023-11-04T00:00:00+00:00 [queued]>
[2023-11-05T21:55:51.595+0000] {taskinstance.py:1159} INFO - Dependencies all met for dep_context=requeueable deps ti=<TaskInstance: fetch_google_data_v03.3rd_task scheduled__2023-11-04T00:00:00+00:00 [queued]>
[2023-11-05T21:55:51.597+0000] {taskinstance.py:1361} INFO - Starting attempt 4 of 6
[2023-11-05T21:55:51.622+0000] {taskinstance.py:1382} INFO - Executing <Task(BashOperator): 3rd_task> on 2023-11-04 00:00:00+00:00
[2023-11-05T21:55:51.633+0000] {standard_task_runner.py:57} INFO - Started process 44833 to run task
[2023-11-05T21:55:51.637+0000] {standard_task_runner.py:84} INFO - Running: ['***', 'tasks', 'run', 'fetch_google_data_v03', '3rd_task', 'scheduled__2023-11-04T00:00:00+00:00', '--job-id', '231', '--raw', '--subdir', 'DAGS_FOLDER/fetch_data.py', '--cfg-path', '/tmp/tmph6liu_nh']
[2023-11-05T21:55:51.646+0000] {standard_task_runner.py:85} INFO - Job 231: Subtask 3rd_task
[2023-11-05T21:55:51.740+0000] {logging_mixin.py:151} INFO - Changing /opt/***/logs/dag_id=fetch_google_data_v03/run_id=scheduled__2023-11-04T00:00:00+00:00/task_id=3rd_task permission to 509
[2023-11-05T21:55:51.749+0000] {task_command.py:416} INFO - Running <TaskInstance: fetch_google_data_v03.3rd_task scheduled__2023-11-04T00:00:00+00:00 [running]> on host 2e5f9e164ff4
[2023-11-05T21:55:51.877+0000] {taskinstance.py:1662} INFO - Exporting env vars: AIRFLOW_CTX_DAG_OWNER='Toema' AIRFLOW_CTX_DAG_ID='fetch_google_data_v03' AIRFLOW_CTX_TASK_ID='3rd_task' AIRFLOW_CTX_EXECUTION_DATE='2023-11-04T00:00:00+00:00' AIRFLOW_CTX_TRY_NUMBER='4' AIRFLOW_CTX_DAG_RUN_ID='scheduled__2023-11-04T00:00:00+00:00'
[2023-11-05T21:55:51.879+0000] {subprocess.py:63} INFO - Tmp dir root location: /tmp
[2023-11-05T21:55:51.884+0000] {subprocess.py:75} INFO - Running command: ['/bin/bash', '-c', 'python /opt/***/dags/src/scripts/fetch_automatic_downloads.py']
[2023-11-05T21:55:51.903+0000] {subprocess.py:86} INFO - Output:
[2023-11-05T21:55:53.614+0000] {subprocess.py:93} INFO - Traceback (most recent call last):
[2023-11-05T21:55:53.617+0000] {subprocess.py:93} INFO -   File "/opt/***/dags/src/scripts/fetch_automatic_downloads.py", line 42, in <module>
[2023-11-05T21:55:53.620+0000] {subprocess.py:93} INFO -     automatic_downloads = config.read_config(cc_by=True, cc_by_sa=True, google_tos=True, cc_by_nc=True,
[2023-11-05T21:55:53.622+0000] {subprocess.py:93} INFO -   File "/opt/***/dags/src/scripts/../../src/pipeline/config.py", line 77, in read_config
[2023-11-05T21:55:53.625+0000] {subprocess.py:93} INFO -     with open(source_file, 'r', encoding="UTF-8", errors="ignore") as file:
[2023-11-05T21:55:53.629+0000] {subprocess.py:93} INFO - OSError: [Errno 5] Input/output error: '/opt/***/dags/src/config/sources/norway_fhi.yaml'
[2023-11-05T21:55:53.689+0000] {subprocess.py:97} INFO - Command exited with return code 1
[2023-11-05T21:55:53.726+0000] {taskinstance.py:1937} ERROR - Task failed with exception
Traceback (most recent call last):
  File "/home/airflow/.local/lib/python3.8/site-packages/airflow/operators/bash.py", line 210, in execute
    raise AirflowException(
airflow.exceptions.AirflowException: Bash command failed. The command returned a non-zero exit code 1.
[2023-11-05T21:55:53.750+0000] {taskinstance.py:1400} INFO - Marking task as UP_FOR_RETRY. dag_id=fetch_google_data_v03, task_id=3rd_task, execution_date=20231104T000000, start_date=20231105T215551, end_date=20231105T215553
[2023-11-05T21:55:53.810+0000] {standard_task_runner.py:104} ERROR - Failed to execute job 231 for task 3rd_task (Bash command failed. The command returned a non-zero exit code 1.; 44833)
[2023-11-05T21:55:54.291+0000] {local_task_job_runner.py:228} INFO - Task exited with return code 1
[2023-11-05T21:55:54.361+0000] {taskinstance.py:2778} INFO - 0 downstream tasks scheduled from follow-on schedule check
