[2023-11-04T23:09:13.329+0000] {logging_mixin.py:151} INFO - Changing /opt/***/logs/dag_id=dag_for_s3_files_checker_v01/run_id=manual__2023-11-04T23:09:09.163430+00:00/task_id=32rd_task permission to 509
[2023-11-04T23:09:13.386+0000] {logging_mixin.py:151} INFO - Changing /opt/***/logs/dag_id=dag_for_s3_files_checker_v01/run_id=manual__2023-11-04T23:09:09.163430+00:00/task_id=32rd_task permission to 509
[2023-11-04T23:09:13.453+0000] {taskinstance.py:1159} INFO - Dependencies all met for dep_context=non-requeueable deps ti=<TaskInstance: dag_for_s3_files_checker_v01.32rd_task manual__2023-11-04T23:09:09.163430+00:00 [queued]>
[2023-11-04T23:09:13.472+0000] {taskinstance.py:1159} INFO - Dependencies all met for dep_context=requeueable deps ti=<TaskInstance: dag_for_s3_files_checker_v01.32rd_task manual__2023-11-04T23:09:09.163430+00:00 [queued]>
[2023-11-04T23:09:13.474+0000] {taskinstance.py:1361} INFO - Starting attempt 1 of 6
[2023-11-04T23:09:13.504+0000] {taskinstance.py:1382} INFO - Executing <Task(BashOperator): 32rd_task> on 2023-11-04 23:09:09.163430+00:00
[2023-11-04T23:09:13.513+0000] {standard_task_runner.py:57} INFO - Started process 6064 to run task
[2023-11-04T23:09:13.517+0000] {standard_task_runner.py:84} INFO - Running: ['***', 'tasks', 'run', 'dag_for_s3_files_checker_v01', '32rd_task', 'manual__2023-11-04T23:09:09.163430+00:00', '--job-id', '94', '--raw', '--subdir', 'DAGS_FOLDER/check_S3_files.py', '--cfg-path', '/tmp/tmpvildebov']
[2023-11-04T23:09:13.521+0000] {standard_task_runner.py:85} INFO - Job 94: Subtask 32rd_task
[2023-11-04T23:09:13.600+0000] {logging_mixin.py:151} INFO - Changing /opt/***/logs/dag_id=dag_for_s3_files_checker_v01/run_id=manual__2023-11-04T23:09:09.163430+00:00/task_id=32rd_task permission to 509
[2023-11-04T23:09:13.608+0000] {task_command.py:416} INFO - Running <TaskInstance: dag_for_s3_files_checker_v01.32rd_task manual__2023-11-04T23:09:09.163430+00:00 [running]> on host c1553d42a04f
[2023-11-04T23:09:13.743+0000] {taskinstance.py:1662} INFO - Exporting env vars: AIRFLOW_CTX_DAG_OWNER='Toema' AIRFLOW_CTX_DAG_ID='dag_for_s3_files_checker_v01' AIRFLOW_CTX_TASK_ID='32rd_task' AIRFLOW_CTX_EXECUTION_DATE='2023-11-04T23:09:09.163430+00:00' AIRFLOW_CTX_TRY_NUMBER='1' AIRFLOW_CTX_DAG_RUN_ID='manual__2023-11-04T23:09:09.163430+00:00'
[2023-11-04T23:09:13.747+0000] {subprocess.py:63} INFO - Tmp dir root location: /tmp
[2023-11-04T23:09:13.750+0000] {subprocess.py:75} INFO - Running command: ['/bin/bash', '-c', 'python /opt/***/dags/src/scripts/fetch_automatic_downloads.py']
[2023-11-04T23:09:13.765+0000] {subprocess.py:86} INFO - Output:
[2023-11-04T23:09:15.114+0000] {subprocess.py:93} INFO - Traceback (most recent call last):
[2023-11-04T23:09:15.115+0000] {subprocess.py:93} INFO -   File "/opt/***/dags/src/scripts/fetch_automatic_downloads.py", line 42, in <module>
[2023-11-04T23:09:15.116+0000] {subprocess.py:93} INFO -     automatic_downloads = config.read_config(cc_by=True, cc_by_sa=True, google_tos=True, cc_by_nc=True,
[2023-11-04T23:09:15.117+0000] {subprocess.py:93} INFO -   File "/opt/***/dags/src/scripts/../../src/pipeline/config.py", line 71, in read_config
[2023-11-04T23:09:15.118+0000] {subprocess.py:93} INFO -     sources_with_data = get_sources_with_data()
[2023-11-04T23:09:15.119+0000] {subprocess.py:93} INFO -   File "/opt/***/dags/src/scripts/../../src/pipeline/config.py", line 55, in get_sources_with_data
[2023-11-04T23:09:15.120+0000] {subprocess.py:93} INFO -     downloaded_sources = [f.name for f in os.scandir(downloaded_dir) if f.is_dir()]
[2023-11-04T23:09:15.121+0000] {subprocess.py:93} INFO - FileNotFoundError: [Errno 2] No such file or directory: '/opt/***/dags/data/inputs/downloaded'
[2023-11-04T23:09:15.130+0000] {subprocess.py:97} INFO - Command exited with return code 1
[2023-11-04T23:09:15.148+0000] {taskinstance.py:1937} ERROR - Task failed with exception
Traceback (most recent call last):
  File "/home/airflow/.local/lib/python3.8/site-packages/airflow/operators/bash.py", line 210, in execute
    raise AirflowException(
airflow.exceptions.AirflowException: Bash command failed. The command returned a non-zero exit code 1.
[2023-11-04T23:09:15.162+0000] {taskinstance.py:1400} INFO - Marking task as UP_FOR_RETRY. dag_id=dag_for_s3_files_checker_v01, task_id=32rd_task, execution_date=20231104T230909, start_date=20231104T230913, end_date=20231104T230915
[2023-11-04T23:09:15.187+0000] {standard_task_runner.py:104} ERROR - Failed to execute job 94 for task 32rd_task (Bash command failed. The command returned a non-zero exit code 1.; 6064)
[2023-11-04T23:09:15.220+0000] {local_task_job_runner.py:228} INFO - Task exited with return code 1
[2023-11-04T23:09:15.252+0000] {taskinstance.py:2778} INFO - 0 downstream tasks scheduled from follow-on schedule check
