[2023-11-05T00:18:50.225+0000] {logging_mixin.py:151} INFO - Changing /opt/***/logs/dag_id=fetch_google_data_v01/run_id=manual__2023-11-04T23:48:36.176271+00:00/task_id=3rd_task permission to 509
[2023-11-05T00:18:50.317+0000] {logging_mixin.py:151} INFO - Changing /opt/***/logs/dag_id=fetch_google_data_v01/run_id=manual__2023-11-04T23:48:36.176271+00:00/task_id=3rd_task permission to 509
[2023-11-05T00:18:50.431+0000] {taskinstance.py:1159} INFO - Dependencies all met for dep_context=non-requeueable deps ti=<TaskInstance: fetch_google_data_v01.3rd_task manual__2023-11-04T23:48:36.176271+00:00 [queued]>
[2023-11-05T00:18:50.470+0000] {taskinstance.py:1159} INFO - Dependencies all met for dep_context=requeueable deps ti=<TaskInstance: fetch_google_data_v01.3rd_task manual__2023-11-04T23:48:36.176271+00:00 [queued]>
[2023-11-05T00:18:50.473+0000] {taskinstance.py:1361} INFO - Starting attempt 4 of 6
[2023-11-05T00:18:50.524+0000] {taskinstance.py:1382} INFO - Executing <Task(BashOperator): 3rd_task> on 2023-11-04 23:48:36.176271+00:00
[2023-11-05T00:18:50.538+0000] {standard_task_runner.py:57} INFO - Started process 3969 to run task
[2023-11-05T00:18:50.544+0000] {standard_task_runner.py:84} INFO - Running: ['***', 'tasks', 'run', 'fetch_google_data_v01', '3rd_task', 'manual__2023-11-04T23:48:36.176271+00:00', '--job-id', '143', '--raw', '--subdir', 'DAGS_FOLDER/fetch_data.py', '--cfg-path', '/tmp/tmpilha9uob']
[2023-11-05T00:18:50.552+0000] {standard_task_runner.py:85} INFO - Job 143: Subtask 3rd_task
[2023-11-05T00:18:50.686+0000] {logging_mixin.py:151} INFO - Changing /opt/***/logs/dag_id=fetch_google_data_v01/run_id=manual__2023-11-04T23:48:36.176271+00:00/task_id=3rd_task permission to 509
[2023-11-05T00:18:50.700+0000] {task_command.py:416} INFO - Running <TaskInstance: fetch_google_data_v01.3rd_task manual__2023-11-04T23:48:36.176271+00:00 [running]> on host 264d7b91d87b
[2023-11-05T00:18:50.862+0000] {taskinstance.py:1662} INFO - Exporting env vars: AIRFLOW_CTX_DAG_OWNER='Toema' AIRFLOW_CTX_DAG_ID='fetch_google_data_v01' AIRFLOW_CTX_TASK_ID='3rd_task' AIRFLOW_CTX_EXECUTION_DATE='2023-11-04T23:48:36.176271+00:00' AIRFLOW_CTX_TRY_NUMBER='4' AIRFLOW_CTX_DAG_RUN_ID='manual__2023-11-04T23:48:36.176271+00:00'
[2023-11-05T00:18:50.865+0000] {subprocess.py:63} INFO - Tmp dir root location: /tmp
[2023-11-05T00:18:50.868+0000] {subprocess.py:75} INFO - Running command: ['/bin/bash', '-c', 'python /opt/***/dags/src/scripts/fetch_automatic_downloads.py']
[2023-11-05T00:18:50.891+0000] {subprocess.py:86} INFO - Output:
[2023-11-05T00:18:51.140+0000] {subprocess.py:93} INFO - python: can't open file '/opt/***/dags/src/scripts/fetch_automatic_downloads.py': [Errno 5] Input/output error
[2023-11-05T00:18:51.154+0000] {subprocess.py:97} INFO - Command exited with return code 2
[2023-11-05T00:18:51.181+0000] {taskinstance.py:1937} ERROR - Task failed with exception
Traceback (most recent call last):
  File "/home/airflow/.local/lib/python3.8/site-packages/airflow/operators/bash.py", line 210, in execute
    raise AirflowException(
airflow.exceptions.AirflowException: Bash command failed. The command returned a non-zero exit code 2.
[2023-11-05T00:18:51.192+0000] {taskinstance.py:1400} INFO - Marking task as UP_FOR_RETRY. dag_id=fetch_google_data_v01, task_id=3rd_task, execution_date=20231104T234836, start_date=20231105T001850, end_date=20231105T001851
[2023-11-05T00:18:51.227+0000] {standard_task_runner.py:104} ERROR - Failed to execute job 143 for task 3rd_task (Bash command failed. The command returned a non-zero exit code 2.; 3969)
[2023-11-05T00:18:51.284+0000] {local_task_job_runner.py:228} INFO - Task exited with return code 1
[2023-11-05T00:18:51.450+0000] {taskinstance.py:2778} INFO - 0 downstream tasks scheduled from follow-on schedule check
