[2023-11-07T01:43:09.431+0000] {logging_mixin.py:151} INFO - Changing /opt/***/logs/dag_id=export_google_data_v02/run_id=scheduled__2023-11-02T00:00:00+00:00/task_id=3rd_task permission to 509
[2023-11-07T01:43:09.627+0000] {logging_mixin.py:151} INFO - Changing /opt/***/logs/dag_id=export_google_data_v02/run_id=scheduled__2023-11-02T00:00:00+00:00/task_id=3rd_task permission to 509
[2023-11-07T01:43:10.430+0000] {taskinstance.py:1149} INFO - Dependencies not met for <TaskInstance: export_google_data_v02.3rd_task scheduled__2023-11-02T00:00:00+00:00 [up_for_retry]>, dependency 'Not In Retry Period' FAILED: Task is not ready for retry yet but will be retried automatically. Current date is 2023-11-07T01:43:10.430113+00:00 and task will be retried at 2023-11-07T01:53:02.516112+00:00.
[2023-11-07T01:43:10.464+0000] {local_task_job_runner.py:154} INFO - Task is not able to be run
[2023-11-07T01:53:07.347+0000] {logging_mixin.py:151} INFO - Changing /opt/***/logs/dag_id=export_google_data_v02/run_id=scheduled__2023-11-02T00:00:00+00:00/task_id=3rd_task permission to 509
[2023-11-07T01:53:07.531+0000] {logging_mixin.py:151} INFO - Changing /opt/***/logs/dag_id=export_google_data_v02/run_id=scheduled__2023-11-02T00:00:00+00:00/task_id=3rd_task permission to 509
[2023-11-07T01:53:08.009+0000] {taskinstance.py:1159} INFO - Dependencies all met for dep_context=non-requeueable deps ti=<TaskInstance: export_google_data_v02.3rd_task scheduled__2023-11-02T00:00:00+00:00 [queued]>
[2023-11-07T01:53:08.099+0000] {taskinstance.py:1159} INFO - Dependencies all met for dep_context=requeueable deps ti=<TaskInstance: export_google_data_v02.3rd_task scheduled__2023-11-02T00:00:00+00:00 [queued]>
[2023-11-07T01:53:08.105+0000] {taskinstance.py:1361} INFO - Starting attempt 5 of 6
[2023-11-07T01:53:08.199+0000] {taskinstance.py:1382} INFO - Executing <Task(BashOperator): 3rd_task> on 2023-11-02 00:00:00+00:00
[2023-11-07T01:53:08.306+0000] {standard_task_runner.py:57} INFO - Started process 13185 to run task
[2023-11-07T01:53:08.319+0000] {standard_task_runner.py:84} INFO - Running: ['***', 'tasks', 'run', 'export_google_data_v02', '3rd_task', 'scheduled__2023-11-02T00:00:00+00:00', '--job-id', '300', '--raw', '--subdir', 'DAGS_FOLDER/export_data.py', '--cfg-path', '/tmp/tmp7yc591d9']
[2023-11-07T01:53:08.329+0000] {standard_task_runner.py:85} INFO - Job 300: Subtask 3rd_task
[2023-11-07T01:53:08.693+0000] {logging_mixin.py:151} INFO - Changing /opt/***/logs/dag_id=export_google_data_v02/run_id=scheduled__2023-11-02T00:00:00+00:00/task_id=3rd_task permission to 509
[2023-11-07T01:53:08.733+0000] {task_command.py:416} INFO - Running <TaskInstance: export_google_data_v02.3rd_task scheduled__2023-11-02T00:00:00+00:00 [running]> on host c4630ce72677
[2023-11-07T01:53:09.501+0000] {taskinstance.py:1662} INFO - Exporting env vars: AIRFLOW_CTX_DAG_OWNER='Toema' AIRFLOW_CTX_DAG_ID='export_google_data_v02' AIRFLOW_CTX_TASK_ID='3rd_task' AIRFLOW_CTX_EXECUTION_DATE='2023-11-02T00:00:00+00:00' AIRFLOW_CTX_TRY_NUMBER='5' AIRFLOW_CTX_DAG_RUN_ID='scheduled__2023-11-02T00:00:00+00:00'
[2023-11-07T01:53:09.514+0000] {subprocess.py:63} INFO - Tmp dir root location: /tmp
[2023-11-07T01:53:09.562+0000] {subprocess.py:75} INFO - Running command: ['/bin/bash', '-c', 'python /opt/***/dags/src/scripts/export_data.py']
[2023-11-07T01:53:09.630+0000] {subprocess.py:86} INFO - Output:
[2023-11-07T01:54:52.712+0000] {job.py:219} ERROR - Job heartbeat got an exception
Traceback (most recent call last):
  File "/home/airflow/.local/lib/python3.8/site-packages/sqlalchemy/engine/base.py", line 3371, in _wrap_pool_connect
    return fn()
  File "/home/airflow/.local/lib/python3.8/site-packages/sqlalchemy/pool/base.py", line 327, in connect
    return _ConnectionFairy._checkout(self)
  File "/home/airflow/.local/lib/python3.8/site-packages/sqlalchemy/pool/base.py", line 894, in _checkout
    fairy = _ConnectionRecord.checkout(pool)
  File "/home/airflow/.local/lib/python3.8/site-packages/sqlalchemy/pool/base.py", line 493, in checkout
    rec = pool._do_get()
  File "/home/airflow/.local/lib/python3.8/site-packages/sqlalchemy/pool/impl.py", line 256, in _do_get
    return self._create_connection()
  File "/home/airflow/.local/lib/python3.8/site-packages/sqlalchemy/pool/base.py", line 273, in _create_connection
    return _ConnectionRecord(self)
  File "/home/airflow/.local/lib/python3.8/site-packages/sqlalchemy/pool/base.py", line 388, in __init__
    self.__connect()
  File "/home/airflow/.local/lib/python3.8/site-packages/sqlalchemy/pool/base.py", line 691, in __connect
    pool.logger.debug("Error on connect(): %s", e)
  File "/home/airflow/.local/lib/python3.8/site-packages/sqlalchemy/util/langhelpers.py", line 70, in __exit__
    compat.raise_(
  File "/home/airflow/.local/lib/python3.8/site-packages/sqlalchemy/util/compat.py", line 211, in raise_
    raise exception
  File "/home/airflow/.local/lib/python3.8/site-packages/sqlalchemy/pool/base.py", line 686, in __connect
    self.dbapi_connection = connection = pool._invoke_creator(self)
  File "/home/airflow/.local/lib/python3.8/site-packages/sqlalchemy/engine/create.py", line 574, in connect
    return dialect.connect(*cargs, **cparams)
  File "/home/airflow/.local/lib/python3.8/site-packages/sqlalchemy/engine/default.py", line 598, in connect
    return self.dbapi.connect(*cargs, **cparams)
  File "/home/airflow/.local/lib/python3.8/site-packages/psycopg2/__init__.py", line 122, in connect
    conn = _connect(dsn, connection_factory=connection_factory, **kwasync)
psycopg2.OperationalError: could not translate host name "postgres" to address: Temporary failure in name resolution


The above exception was the direct cause of the following exception:

Traceback (most recent call last):
  File "/home/airflow/.local/lib/python3.8/site-packages/airflow/jobs/job.py", line 190, in heartbeat
    session.merge(self)
  File "/home/airflow/.local/lib/python3.8/site-packages/sqlalchemy/orm/session.py", line 3056, in merge
    return self._merge(
  File "/home/airflow/.local/lib/python3.8/site-packages/sqlalchemy/orm/session.py", line 3136, in _merge
    merged = self.get(
  File "/home/airflow/.local/lib/python3.8/site-packages/sqlalchemy/orm/session.py", line 2853, in get
    return self._get_impl(
  File "/home/airflow/.local/lib/python3.8/site-packages/sqlalchemy/orm/session.py", line 2975, in _get_impl
    return db_load_fn(
  File "/home/airflow/.local/lib/python3.8/site-packages/sqlalchemy/orm/loading.py", line 530, in load_on_pk_identity
    session.execute(
  File "/home/airflow/.local/lib/python3.8/site-packages/sqlalchemy/orm/session.py", line 1716, in execute
    conn = self._connection_for_bind(bind)
  File "/home/airflow/.local/lib/python3.8/site-packages/sqlalchemy/orm/session.py", line 1555, in _connection_for_bind
    return self._transaction._connection_for_bind(
  File "/home/airflow/.local/lib/python3.8/site-packages/sqlalchemy/orm/session.py", line 750, in _connection_for_bind
    conn = bind.connect()
  File "/home/airflow/.local/lib/python3.8/site-packages/sqlalchemy/future/engine.py", line 406, in connect
    return super(Engine, self).connect()
  File "/home/airflow/.local/lib/python3.8/site-packages/sqlalchemy/engine/base.py", line 3325, in connect
    return self._connection_cls(self, close_with_result=close_with_result)
  File "/home/airflow/.local/lib/python3.8/site-packages/sqlalchemy/engine/base.py", line 96, in __init__
    else engine.raw_connection()
  File "/home/airflow/.local/lib/python3.8/site-packages/sqlalchemy/engine/base.py", line 3404, in raw_connection
    return self._wrap_pool_connect(self.pool.connect, _connection)
  File "/home/airflow/.local/lib/python3.8/site-packages/sqlalchemy/engine/base.py", line 3374, in _wrap_pool_connect
    Connection._handle_dbapi_exception_noconnection(
  File "/home/airflow/.local/lib/python3.8/site-packages/sqlalchemy/engine/base.py", line 2208, in _handle_dbapi_exception_noconnection
    util.raise_(
  File "/home/airflow/.local/lib/python3.8/site-packages/sqlalchemy/util/compat.py", line 211, in raise_
    raise exception
  File "/home/airflow/.local/lib/python3.8/site-packages/sqlalchemy/engine/base.py", line 3371, in _wrap_pool_connect
    return fn()
  File "/home/airflow/.local/lib/python3.8/site-packages/sqlalchemy/pool/base.py", line 327, in connect
    return _ConnectionFairy._checkout(self)
  File "/home/airflow/.local/lib/python3.8/site-packages/sqlalchemy/pool/base.py", line 894, in _checkout
    fairy = _ConnectionRecord.checkout(pool)
  File "/home/airflow/.local/lib/python3.8/site-packages/sqlalchemy/pool/base.py", line 493, in checkout
    rec = pool._do_get()
  File "/home/airflow/.local/lib/python3.8/site-packages/sqlalchemy/pool/impl.py", line 256, in _do_get
    return self._create_connection()
  File "/home/airflow/.local/lib/python3.8/site-packages/sqlalchemy/pool/base.py", line 273, in _create_connection
    return _ConnectionRecord(self)
  File "/home/airflow/.local/lib/python3.8/site-packages/sqlalchemy/pool/base.py", line 388, in __init__
    self.__connect()
  File "/home/airflow/.local/lib/python3.8/site-packages/sqlalchemy/pool/base.py", line 691, in __connect
    pool.logger.debug("Error on connect(): %s", e)
  File "/home/airflow/.local/lib/python3.8/site-packages/sqlalchemy/util/langhelpers.py", line 70, in __exit__
    compat.raise_(
  File "/home/airflow/.local/lib/python3.8/site-packages/sqlalchemy/util/compat.py", line 211, in raise_
    raise exception
  File "/home/airflow/.local/lib/python3.8/site-packages/sqlalchemy/pool/base.py", line 686, in __connect
    self.dbapi_connection = connection = pool._invoke_creator(self)
  File "/home/airflow/.local/lib/python3.8/site-packages/sqlalchemy/engine/create.py", line 574, in connect
    return dialect.connect(*cargs, **cparams)
  File "/home/airflow/.local/lib/python3.8/site-packages/sqlalchemy/engine/default.py", line 598, in connect
    return self.dbapi.connect(*cargs, **cparams)
  File "/home/airflow/.local/lib/python3.8/site-packages/psycopg2/__init__.py", line 122, in connect
    conn = _connect(dsn, connection_factory=connection_factory, **kwasync)
sqlalchemy.exc.OperationalError: (psycopg2.OperationalError) could not translate host name "postgres" to address: Temporary failure in name resolution

(Background on this error at: https://sqlalche.me/e/14/e3q8)
[2023-11-07T01:55:34.899+0000] {subprocess.py:97} INFO - Command exited with return code -9
[2023-11-07T01:55:39.519+0000] {taskinstance.py:1937} ERROR - Task failed with exception
Traceback (most recent call last):
  File "/home/airflow/.local/lib/python3.8/site-packages/airflow/operators/bash.py", line 210, in execute
    raise AirflowException(
airflow.exceptions.AirflowException: Bash command failed. The command returned a non-zero exit code -9.
[2023-11-07T01:55:39.718+0000] {taskinstance.py:1400} INFO - Marking task as UP_FOR_RETRY. dag_id=export_google_data_v02, task_id=3rd_task, execution_date=20231102T000000, start_date=20231107T015308, end_date=20231107T015539
[2023-11-07T01:55:41.046+0000] {standard_task_runner.py:104} ERROR - Failed to execute job 300 for task 3rd_task (Bash command failed. The command returned a non-zero exit code -9.; 13185)
[2023-11-07T01:55:42.667+0000] {local_task_job_runner.py:228} INFO - Task exited with return code 1
[2023-11-07T01:55:43.379+0000] {taskinstance.py:2778} INFO - 0 downstream tasks scheduled from follow-on schedule check
