[2023-11-08T00:19:48.945+0000] {logging_mixin.py:151} INFO - Changing /opt/***/logs/dag_id=check_S3_minio_bucket_v01/run_id=manual__2023-11-08T00:19:03.455730+00:00/task_id=12st_task permission to 509
[2023-11-08T00:19:49.016+0000] {logging_mixin.py:151} INFO - Changing /opt/***/logs/dag_id=check_S3_minio_bucket_v01/run_id=manual__2023-11-08T00:19:03.455730+00:00/task_id=12st_task permission to 509
[2023-11-08T00:19:49.075+0000] {taskinstance.py:1159} INFO - Dependencies all met for dep_context=non-requeueable deps ti=<TaskInstance: check_S3_minio_bucket_v01.12st_task manual__2023-11-08T00:19:03.455730+00:00 [queued]>
[2023-11-08T00:19:49.103+0000] {taskinstance.py:1159} INFO - Dependencies all met for dep_context=requeueable deps ti=<TaskInstance: check_S3_minio_bucket_v01.12st_task manual__2023-11-08T00:19:03.455730+00:00 [queued]>
[2023-11-08T00:19:49.105+0000] {taskinstance.py:1361} INFO - Starting attempt 1 of 6
[2023-11-08T00:19:49.143+0000] {taskinstance.py:1382} INFO - Executing <Task(S3KeySensor): 12st_task> on 2023-11-08 00:19:03.455730+00:00
[2023-11-08T00:19:49.158+0000] {standard_task_runner.py:57} INFO - Started process 2339 to run task
[2023-11-08T00:19:49.163+0000] {standard_task_runner.py:84} INFO - Running: ['***', 'tasks', 'run', 'check_S3_minio_bucket_v01', '12st_task', 'manual__2023-11-08T00:19:03.455730+00:00', '--job-id', '391', '--raw', '--subdir', 'DAGS_FOLDER/check_S3_bucket.py', '--cfg-path', '/tmp/tmpzxabqk5c']
[2023-11-08T00:19:49.168+0000] {standard_task_runner.py:85} INFO - Job 391: Subtask 12st_task
[2023-11-08T00:19:49.295+0000] {logging_mixin.py:151} INFO - Changing /opt/***/logs/dag_id=check_S3_minio_bucket_v01/run_id=manual__2023-11-08T00:19:03.455730+00:00/task_id=12st_task permission to 509
[2023-11-08T00:19:49.307+0000] {task_command.py:416} INFO - Running <TaskInstance: check_S3_minio_bucket_v01.12st_task manual__2023-11-08T00:19:03.455730+00:00 [running]> on host 326a1fe25163
[2023-11-08T00:19:49.527+0000] {taskinstance.py:1662} INFO - Exporting env vars: AIRFLOW_CTX_DAG_OWNER='Toema' AIRFLOW_CTX_DAG_ID='check_S3_minio_bucket_v01' AIRFLOW_CTX_TASK_ID='12st_task' AIRFLOW_CTX_EXECUTION_DATE='2023-11-08T00:19:03.455730+00:00' AIRFLOW_CTX_TRY_NUMBER='1' AIRFLOW_CTX_DAG_RUN_ID='manual__2023-11-08T00:19:03.455730+00:00'
[2023-11-08T00:19:49.530+0000] {s3.py:106} INFO - Poking for key : s3://***/country_wise_latest.csv
[2023-11-08T00:19:49.571+0000] {base.py:73} INFO - Using connection ID 's3_minio_conn' for task execution.
[2023-11-08T00:19:49.576+0000] {connection_wrapper.py:343} INFO - AWS Connection (conn_id='s3_minio_conn', conn_type='aws') credentials retrieved from extra.
[2023-11-08T00:20:03.265+0000] {taskinstance.py:1937} ERROR - Task failed with exception
Traceback (most recent call last):
  File "/home/airflow/.local/lib/python3.8/site-packages/urllib3/connection.py", line 174, in _new_conn
    conn = connection.create_connection(
  File "/home/airflow/.local/lib/python3.8/site-packages/urllib3/util/connection.py", line 95, in create_connection
    raise err
  File "/home/airflow/.local/lib/python3.8/site-packages/urllib3/util/connection.py", line 85, in create_connection
    sock.connect(sa)
ConnectionRefusedError: [Errno 111] Connection refused

During handling of the above exception, another exception occurred:

Traceback (most recent call last):
  File "/home/airflow/.local/lib/python3.8/site-packages/botocore/httpsession.py", line 465, in send
    urllib_response = conn.urlopen(
  File "/home/airflow/.local/lib/python3.8/site-packages/urllib3/connectionpool.py", line 798, in urlopen
    retries = retries.increment(
  File "/home/airflow/.local/lib/python3.8/site-packages/urllib3/util/retry.py", line 525, in increment
    raise six.reraise(type(error), error, _stacktrace)
  File "/home/airflow/.local/lib/python3.8/site-packages/urllib3/packages/six.py", line 770, in reraise
    raise value
  File "/home/airflow/.local/lib/python3.8/site-packages/urllib3/connectionpool.py", line 714, in urlopen
    httplib_response = self._make_request(
  File "/home/airflow/.local/lib/python3.8/site-packages/urllib3/connectionpool.py", line 415, in _make_request
    conn.request(method, url, **httplib_request_kw)
  File "/home/airflow/.local/lib/python3.8/site-packages/botocore/awsrequest.py", line 96, in request
    rval = super().request(method, url, body, headers, *args, **kwargs)
  File "/home/airflow/.local/lib/python3.8/site-packages/urllib3/connection.py", line 244, in request
    super(HTTPConnection, self).request(method, url, body=body, headers=headers)
  File "/usr/local/lib/python3.8/http/client.py", line 1256, in request
    self._send_request(method, url, body, headers, encode_chunked)
  File "/usr/local/lib/python3.8/http/client.py", line 1302, in _send_request
    self.endheaders(body, encode_chunked=encode_chunked)
  File "/usr/local/lib/python3.8/http/client.py", line 1251, in endheaders
    self._send_output(message_body, encode_chunked=encode_chunked)
  File "/home/airflow/.local/lib/python3.8/site-packages/botocore/awsrequest.py", line 123, in _send_output
    self.send(msg)
  File "/home/airflow/.local/lib/python3.8/site-packages/botocore/awsrequest.py", line 223, in send
    return super().send(str)
  File "/usr/local/lib/python3.8/http/client.py", line 951, in send
    self.connect()
  File "/home/airflow/.local/lib/python3.8/site-packages/urllib3/connection.py", line 205, in connect
    conn = self._new_conn()
  File "/home/airflow/.local/lib/python3.8/site-packages/urllib3/connection.py", line 186, in _new_conn
    raise NewConnectionError(
urllib3.exceptions.NewConnectionError: <botocore.awsrequest.AWSHTTPConnection object at 0x7fb5c3746f40>: Failed to establish a new connection: [Errno 111] Connection refused

During handling of the above exception, another exception occurred:

Traceback (most recent call last):
  File "/home/airflow/.local/lib/python3.8/site-packages/airflow/providers/amazon/aws/sensors/s3.py", line 144, in execute
    super().execute(context)
  File "/home/airflow/.local/lib/python3.8/site-packages/airflow/sensors/base.py", line 257, in execute
    raise e
  File "/home/airflow/.local/lib/python3.8/site-packages/airflow/sensors/base.py", line 239, in execute
    poke_return = self.poke(context)
  File "/home/airflow/.local/lib/python3.8/site-packages/airflow/providers/amazon/aws/sensors/s3.py", line 137, in poke
    return self._check_key(self.bucket_key)
  File "/home/airflow/.local/lib/python3.8/site-packages/airflow/providers/amazon/aws/sensors/s3.py", line 125, in _check_key
    obj = self.hook.head_object(key, bucket_name)
  File "/home/airflow/.local/lib/python3.8/site-packages/airflow/providers/amazon/aws/hooks/s3.py", line 136, in wrapper
    return func(*bound_args.args, **bound_args.kwargs)
  File "/home/airflow/.local/lib/python3.8/site-packages/airflow/providers/amazon/aws/hooks/s3.py", line 90, in wrapper
    return func(*bound_args.args, **bound_args.kwargs)
  File "/home/airflow/.local/lib/python3.8/site-packages/airflow/providers/amazon/aws/hooks/s3.py", line 879, in head_object
    return self.get_conn().head_object(Bucket=bucket_name, Key=key)
  File "/home/airflow/.local/lib/python3.8/site-packages/botocore/client.py", line 535, in _api_call
    return self._make_api_call(operation_name, kwargs)
  File "/home/airflow/.local/lib/python3.8/site-packages/botocore/client.py", line 963, in _make_api_call
    http, parsed_response = self._make_request(
  File "/home/airflow/.local/lib/python3.8/site-packages/botocore/client.py", line 986, in _make_request
    return self._endpoint.make_request(operation_model, request_dict)
  File "/home/airflow/.local/lib/python3.8/site-packages/botocore/endpoint.py", line 119, in make_request
    return self._send_request(request_dict, operation_model)
  File "/home/airflow/.local/lib/python3.8/site-packages/botocore/endpoint.py", line 202, in _send_request
    while self._needs_retry(
  File "/home/airflow/.local/lib/python3.8/site-packages/botocore/endpoint.py", line 354, in _needs_retry
    responses = self._event_emitter.emit(
  File "/home/airflow/.local/lib/python3.8/site-packages/botocore/hooks.py", line 412, in emit
    return self._emitter.emit(aliased_event_name, **kwargs)
  File "/home/airflow/.local/lib/python3.8/site-packages/botocore/hooks.py", line 256, in emit
    return self._emit(event_name, kwargs)
  File "/home/airflow/.local/lib/python3.8/site-packages/botocore/hooks.py", line 239, in _emit
    response = handler(**kwargs)
  File "/home/airflow/.local/lib/python3.8/site-packages/botocore/retryhandler.py", line 207, in __call__
    if self._checker(**checker_kwargs):
  File "/home/airflow/.local/lib/python3.8/site-packages/botocore/retryhandler.py", line 284, in __call__
    should_retry = self._should_retry(
  File "/home/airflow/.local/lib/python3.8/site-packages/botocore/retryhandler.py", line 320, in _should_retry
    return self._checker(attempt_number, response, caught_exception)
  File "/home/airflow/.local/lib/python3.8/site-packages/botocore/retryhandler.py", line 363, in __call__
    checker_response = checker(
  File "/home/airflow/.local/lib/python3.8/site-packages/botocore/retryhandler.py", line 247, in __call__
    return self._check_caught_exception(
  File "/home/airflow/.local/lib/python3.8/site-packages/botocore/retryhandler.py", line 416, in _check_caught_exception
    raise caught_exception
  File "/home/airflow/.local/lib/python3.8/site-packages/botocore/endpoint.py", line 281, in _do_get_response
    http_response = self._send(request)
  File "/home/airflow/.local/lib/python3.8/site-packages/botocore/endpoint.py", line 377, in _send
    return self.http_session.send(request)
  File "/home/airflow/.local/lib/python3.8/site-packages/botocore/httpsession.py", line 494, in send
    raise EndpointConnectionError(endpoint_url=request.url, error=e)
botocore.exceptions.EndpointConnectionError: Could not connect to the endpoint URL: "http://localhost:9095/***/country_wise_latest.csv"
[2023-11-08T00:20:03.334+0000] {taskinstance.py:1400} INFO - Marking task as UP_FOR_RETRY. dag_id=check_S3_minio_bucket_v01, task_id=12st_task, execution_date=20231108T001903, start_date=20231108T001949, end_date=20231108T002003
[2023-11-08T00:20:03.382+0000] {standard_task_runner.py:104} ERROR - Failed to execute job 391 for task 12st_task (Could not connect to the endpoint URL: "http://localhost:9095/***/country_wise_latest.csv"; 2339)
[2023-11-08T00:20:03.438+0000] {local_task_job_runner.py:228} INFO - Task exited with return code 1
[2023-11-08T00:20:03.489+0000] {taskinstance.py:2778} INFO - 0 downstream tasks scheduled from follow-on schedule check
