[2023-11-07T04:23:48.134+0000] {logging_mixin.py:151} INFO - Changing /opt/***/logs/dag_id=check_S3_minio_bucket_v01/run_id=manual__2023-11-07T03:41:40.856705+00:00/task_id=12st_task permission to 509
[2023-11-07T04:23:48.202+0000] {logging_mixin.py:151} INFO - Changing /opt/***/logs/dag_id=check_S3_minio_bucket_v01/run_id=manual__2023-11-07T03:41:40.856705+00:00/task_id=12st_task permission to 509
[2023-11-07T04:23:48.252+0000] {taskinstance.py:1159} INFO - Dependencies all met for dep_context=non-requeueable deps ti=<TaskInstance: check_S3_minio_bucket_v01.12st_task manual__2023-11-07T03:41:40.856705+00:00 [queued]>
[2023-11-07T04:23:48.277+0000] {taskinstance.py:1159} INFO - Dependencies all met for dep_context=requeueable deps ti=<TaskInstance: check_S3_minio_bucket_v01.12st_task manual__2023-11-07T03:41:40.856705+00:00 [queued]>
[2023-11-07T04:23:48.278+0000] {taskinstance.py:1361} INFO - Starting attempt 5 of 6
[2023-11-07T04:23:48.319+0000] {taskinstance.py:1382} INFO - Executing <Task(S3KeySensor): 12st_task> on 2023-11-07 03:41:40.856705+00:00
[2023-11-07T04:23:48.339+0000] {standard_task_runner.py:57} INFO - Started process 38931 to run task
[2023-11-07T04:23:48.346+0000] {standard_task_runner.py:84} INFO - Running: ['***', 'tasks', 'run', 'check_S3_minio_bucket_v01', '12st_task', 'manual__2023-11-07T03:41:40.856705+00:00', '--job-id', '373', '--raw', '--subdir', 'DAGS_FOLDER/check_S3_bucket.py', '--cfg-path', '/tmp/tmpt8wb93nl']
[2023-11-07T04:23:48.364+0000] {standard_task_runner.py:85} INFO - Job 373: Subtask 12st_task
[2023-11-07T04:23:48.480+0000] {logging_mixin.py:151} INFO - Changing /opt/***/logs/dag_id=check_S3_minio_bucket_v01/run_id=manual__2023-11-07T03:41:40.856705+00:00/task_id=12st_task permission to 509
[2023-11-07T04:23:48.493+0000] {task_command.py:416} INFO - Running <TaskInstance: check_S3_minio_bucket_v01.12st_task manual__2023-11-07T03:41:40.856705+00:00 [running]> on host c4630ce72677
[2023-11-07T04:23:48.663+0000] {taskinstance.py:1662} INFO - Exporting env vars: AIRFLOW_CTX_DAG_OWNER='Toema' AIRFLOW_CTX_DAG_ID='check_S3_minio_bucket_v01' AIRFLOW_CTX_TASK_ID='12st_task' AIRFLOW_CTX_EXECUTION_DATE='2023-11-07T03:41:40.856705+00:00' AIRFLOW_CTX_TRY_NUMBER='5' AIRFLOW_CTX_DAG_RUN_ID='manual__2023-11-07T03:41:40.856705+00:00'
[2023-11-07T04:23:48.799+0000] {s3.py:106} INFO - Poking for key : s3://***/data.csv
[2023-11-07T04:23:48.821+0000] {base.py:73} INFO - Using connection ID 's3_minio_conn' for task execution.
[2023-11-07T04:23:48.823+0000] {connection_wrapper.py:343} INFO - AWS Connection (conn_id='s3_minio_conn', conn_type='aws') credentials retrieved from extra.
[2023-11-07T04:23:50.593+0000] {taskinstance.py:1937} ERROR - Task failed with exception
Traceback (most recent call last):
  File "/home/airflow/.local/lib/python3.8/site-packages/airflow/providers/amazon/aws/sensors/s3.py", line 144, in execute
    super().execute(context)
  File "/home/airflow/.local/lib/python3.8/site-packages/airflow/sensors/base.py", line 257, in execute
    raise e
  File "/home/airflow/.local/lib/python3.8/site-packages/airflow/sensors/base.py", line 239, in execute
    poke_return = self.poke(context)
  File "/home/airflow/.local/lib/python3.8/site-packages/airflow/providers/amazon/aws/sensors/s3.py", line 137, in poke
    return self._check_key(self.bucket_key)
  File "/home/airflow/.local/lib/python3.8/site-packages/airflow/providers/amazon/aws/sensors/s3.py", line 125, in _check_key
    obj = self.hook.head_object(key, bucket_name)
  File "/home/airflow/.local/lib/python3.8/site-packages/airflow/providers/amazon/aws/hooks/s3.py", line 136, in wrapper
    return func(*bound_args.args, **bound_args.kwargs)
  File "/home/airflow/.local/lib/python3.8/site-packages/airflow/providers/amazon/aws/hooks/s3.py", line 90, in wrapper
    return func(*bound_args.args, **bound_args.kwargs)
  File "/home/airflow/.local/lib/python3.8/site-packages/airflow/providers/amazon/aws/hooks/s3.py", line 884, in head_object
    raise e
  File "/home/airflow/.local/lib/python3.8/site-packages/airflow/providers/amazon/aws/hooks/s3.py", line 879, in head_object
    return self.get_conn().head_object(Bucket=bucket_name, Key=key)
  File "/home/airflow/.local/lib/python3.8/site-packages/botocore/client.py", line 535, in _api_call
    return self._make_api_call(operation_name, kwargs)
  File "/home/airflow/.local/lib/python3.8/site-packages/botocore/client.py", line 980, in _make_api_call
    raise error_class(parsed_response, operation_name)
botocore.exceptions.ClientError: An error occurred (400) when calling the HeadObject operation: Bad Request
[2023-11-07T04:23:50.618+0000] {taskinstance.py:1400} INFO - Marking task as UP_FOR_RETRY. dag_id=check_S3_minio_bucket_v01, task_id=12st_task, execution_date=20231107T034140, start_date=20231107T042348, end_date=20231107T042350
[2023-11-07T04:23:50.661+0000] {standard_task_runner.py:104} ERROR - Failed to execute job 373 for task 12st_task (An error occurred (400) when calling the HeadObject operation: Bad Request; 38931)
[2023-11-07T04:23:50.696+0000] {local_task_job_runner.py:228} INFO - Task exited with return code 1
[2023-11-07T04:23:50.750+0000] {taskinstance.py:2778} INFO - 0 downstream tasks scheduled from follow-on schedule check
